#VRML_SIM R2025a utf8

EXTERNPROTO "https://raw.githubusercontent.com/cyberbotics/webots/R2025a/projects/objects/backgrounds/protos/TexturedBackground.proto"
EXTERNPROTO "https://raw.githubusercontent.com/cyberbotics/webots/R2025a/projects/objects/backgrounds/protos/TexturedBackgroundLight.proto"
EXTERNPROTO "https://raw.githubusercontent.com/cyberbotics/webots/R2025a/projects/objects/floors/protos/RectangleArena.proto"
EXTERNPROTO "https://raw.githubusercontent.com/cyberbotics/webots/R2025a/projects/appearances/protos/BrushedAluminium.proto"
EXTERNPROTO "https://raw.githubusercontent.com/cyberbotics/webots/R2025a/projects/appearances/protos/FlexibleAluminiumDuct.proto"
EXTERNPROTO "https://raw.githubusercontent.com/cyberbotics/webots/R2025a/projects/robots/neuronics/ipr/protos/IprHd6ms180.proto"
EXTERNPROTO "https://raw.githubusercontent.com/cyberbotics/webots/R2025a/projects/objects/fruits/protos/Apple.proto"
EXTERNPROTO "https://raw.githubusercontent.com/cyberbotics/webots/R2025a/projects/objects/fruits/protos/Orange.proto"
EXTERNPROTO "https://raw.githubusercontent.com/cyberbotics/webots/R2025a/projects/objects/kitchen/breakfast/protos/BiscuitBox.proto"
EXTERNPROTO "https://raw.githubusercontent.com/cyberbotics/webots/R2025a/projects/objects/drinks/protos/Can.proto"
EXTERNPROTO "https://raw.githubusercontent.com/cyberbotics/webots/R2025a/projects/objects/animals/protos/Cat.proto"

WorldInfo {
}
Viewpoint {
  orientation 0.08256811783576593 0.9951529960469553 0.05341367218070474 0.6727693064427914
  position -2.6808159640905456 -0.47954087690229963 2.101049408512335
}
TexturedBackground {
}
TexturedBackgroundLight {
}
RectangleArena {
  translation -0.179517 -0.12612 -8.29114e-15
  floorSize 5 5
}
DEF robot2 Robot {
  translation 0.5782288522393504 0.0015381004011479579 0.05908238626846681
  rotation 0.025699080200201934 0.9753566380348703 -0.21913234795022604 0.20797839551287836
  children [
    LED {
      translation 0 0 0.1
      children [
        Shape {
          appearance PBRAppearance {
          }
          geometry Cone {
            bottomRadius 0.05
            height 0.1
          }
        }
      ]
    }
    Gyro {
    }
    Accelerometer {
      name "gps"
    }
    DistanceSensor {
      translation 0.07 0 -5.22482e-07
      rotation 0 -1 0 -5.307179586466759e-06
      name "DS_0"
    }
    DEF LW HingeJoint {
      jointParameters HingeJointParameters {
        position 174.92630250095263
        axis 0 1 0
        anchor 0 0.1 0
      }
      device [
        RotationalMotor {
          name "MLW"
        }
      ]
      endPoint Solid {
        translation -0.00015295584005007787 -0.08000339999999911 0.00010254002255614141
        rotation -0.7902051406846969 0.4334788058477474 -0.43321121928718437 4.479845511155233
        children [
          DEF LW Shape {
            appearance FlexibleAluminiumDuct {
            }
            geometry Cylinder {
              height 0.05
              radius 0.06
            }
          }
        ]
        boundingObject USE LW
        physics Physics {
        }
        linearVelocity 1.3278873515619907e-07 -6.735358955692661e-08 -6.144809343952086e-08
        angularVelocity 8.204195569396376e-07 3.7842035842969727e-06 2.643962089112163e-06
      }
    }
    DEF RW HingeJoint {
      jointParameters HingeJointParameters {
        position 174.92629902703518
        axis 0 1 0
        anchor 0 0.1 0
      }
      device [
        RotationalMotor {
          name "MRW"
        }
      ]
      endPoint Solid {
        translation -6.6577666960840396e-06 0.0799953 1.5975368536738448e-05
        rotation -0.7901904050737312 0.43356114500070914 -0.4331556963438054 4.479915916176133
        children [
          DEF RW Shape {
            appearance FlexibleAluminiumDuct {
            }
            geometry Cylinder {
              height 0.05
              radius 0.06
            }
          }
        ]
        boundingObject USE RW
        physics Physics {
        }
        linearVelocity -5.187906766820039e-07 -1.827255312340451e-08 3.948934111709767e-08
        angularVelocity 2.5336618268822715e-07 -8.832835218754192e-06 2.597640494322498e-06
      }
    }
    DEF body Pose {
      children [
        Shape {
          appearance BrushedAluminium {
          }
          geometry Box {
            size 0.1 0.1 0.1
          }
        }
      ]
    }
  ]
  name "robot2"
  boundingObject USE body
  physics Physics {
  }
  controller "llm_based"
  window "button_input"
  linearVelocity -2.885346995783396e-07 -6.321380267692438e-08 -7.42217783908927e-08
  angularVelocity 1.7901047969781592e-07 -1.0437129167274209e-05 2.6005712185351467e-06
}
IprHd6ms180 {
  hidden position_0_0 -3.748923224882433e-09
  hidden translation_1 0 0 0.2265
  hidden rotation_1 0 0 1 0.12479099621451725
  hidden position_1_0 3.1224955679090837e-07
  hidden translation_2 0 0 0
  hidden rotation_2 -1 0 0 0.5977753122495545
  hidden position_2_0 -9.259703118828485e-07
  hidden translation_3 0 0 0.19
  hidden rotation_3 1 0 0 2.2218009259703115
  hidden position_3_0 3.406761652578993e-07
  hidden translation_4 0 0 0.139
  hidden rotation_4 -1 0 0 2.0333103406761652
  hidden position_4_0 1.4057591197069631e-09
  hidden translation_5 0 0 0.1185
  hidden rotation_5 0 0 1 2.993190002190489
  hidden position_5_0 1.4767477313315693e-08
  hidden position_5_1 6.69832901150922e-09
  hidden translation_6 0 0 0.0983
  hidden rotation_6 0 1 0 0
  hidden translation_11 0.005700184621429127 -1.2349194090655047e-06 0.03249712150134326
  hidden rotation_11 5.577347912006947e-15 1 -1.2594311812064742e-14 0.1919999999999975
  hidden translation_12 1.8462094059090717e-07 -1.2349194120631068e-06 0.08369712150129655
  hidden rotation_12 0.919428741287015 -0.05459998375669798 -0.38944785462131337 3.840175474690895e-15
  hidden translation_14 0 0 0.0983
  hidden rotation_14 0 -1 0 0
  hidden translation_19 -0.007699815378611197 -1.2349190026128554e-06 0.032497121501083415
  hidden rotation_19 -4.1664604932637686e-15 -1 3.179151264083556e-15 -2.949685307179578
  hidden translation_20 1.8462087675308325e-07 -1.2349192647365115e-06 0.08369712150120373
  hidden rotation_20 -3.478062810585193e-15 -1 1.6202834822120095e-15 3.141500000000004
  translation -0.36593 -0.678272 -5.63172e-15
  controller "vlm_controller"
}
Apple {
  hidden linearVelocity_0 0 0 4.736951571767283e-17
  translation 0.02996080511528203 -0.03733659004450169 0.0497645599999917
  rotation -0.7355900851124504 0.4488416488961805 -0.5073937336038116 0.891553498463376
}
BiscuitBox {
  hidden linearVelocity_0 8.920206253129473e-11 -5.142730871555554e-11 3.5982523627086505e-10
  hidden angularVelocity_0 2.5713450486159046e-09 4.460066508226904e-09 6.926961687344004e-17
  translation -0.19753874042706832 -0.370941683135351 -0.00015696004602088962
  rotation -1.625399307556344e-07 -2.831245718445814e-07 -0.9999999999999468 0.0020212078647419613
}
Can {
  hidden linearVelocity_0 2.4027279430358775e-17 -2.487734119361685e-18 4.0602442043672224e-17
  hidden angularVelocity_0 6.709588065149123e-17 2.0315232656083204e-16 -3.451907711282295e-17
  translation -0.51504 -0.368173 0.0609626599999917
  rotation -0.21900663965452308 -0.5104109546542843 0.8315748608250106 2.1394129602886974e-16
}
Cat {
  translation 0.023527 0.315267 0.01
}
Orange {
  hidden linearVelocity_0 0 0 4.736951571681139e-17
  translation -0.3712935482859985 -0.0828688109004673 0.0497645599999917
  rotation 0.940119256322704 0.3198548201027318 0.11776535122138006 1.267269156758256
}
