#VRML_SIM R2025a utf8

EXTERNPROTO "https://raw.githubusercontent.com/cyberbotics/webots/R2025a/projects/objects/backgrounds/protos/TexturedBackground.proto"
EXTERNPROTO "https://raw.githubusercontent.com/cyberbotics/webots/R2025a/projects/objects/backgrounds/protos/TexturedBackgroundLight.proto"
EXTERNPROTO "https://raw.githubusercontent.com/cyberbotics/webots/R2025a/projects/objects/floors/protos/RectangleArena.proto"
EXTERNPROTO "https://raw.githubusercontent.com/cyberbotics/webots/R2025a/projects/appearances/protos/BrushedAluminium.proto"
EXTERNPROTO "https://raw.githubusercontent.com/cyberbotics/webots/R2025a/projects/appearances/protos/FlexibleAluminiumDuct.proto"

WorldInfo {
}
Viewpoint {
  orientation -0.25973702661520415 -0.2213086429359508 0.9399782771782232 4.768840950704826
  position -0.9443648372983966 7.067750340202373 3.7395301293838545
}
TexturedBackground {
}
TexturedBackgroundLight {
}
RectangleArena {
  floorSize 5 5
}
DEF robot2 Robot {
  translation 0.5748844913364871 0.0005300627072717379 0.05908238629814232
  rotation 0.0025983118192265888 0.9999594367603077 0.008624013549277188 0.20291345280715553
  children [
    LED {
      translation 0 0 0.1
      children [
        Shape {
          appearance PBRAppearance {
          }
          geometry Cone {
            bottomRadius 0.05
            height 0.1
          }
        }
      ]
    }
    Gyro {
    }
    Accelerometer {
      name "gps"
    }
    DistanceSensor {
      translation 0.07 0 -5.22482e-07
      rotation 0 -1 0 -5.307179586466759e-06
      name "DS_0"
    }
    DEF LW HingeJoint {
      jointParameters HingeJointParameters {
        position 174.9262996510043
        axis 0 1 0
        anchor 0 0.1 0
      }
      device [
        RotationalMotor {
          name "MLW"
        }
      ]
      endPoint Solid {
        translation -0.00015295613228322156 -0.08000339999999928 0.00010253958663948624
        rotation -0.7902041373583704 0.4334797210116324 -0.43321213368670924 4.479844275761736
        children [
          DEF LW Shape {
            appearance FlexibleAluminiumDuct {
            }
            geometry Cylinder {
              height 0.05
              radius 0.06
            }
          }
        ]
        boundingObject USE LW
        physics Physics {
        }
      }
    }
    DEF RW HingeJoint {
      jointParameters HingeJointParameters {
        position 174.92629902697323
        axis 0 1 0
        anchor 0 0.1 0
      }
      device [
        RotationalMotor {
          name "MRW"
        }
      ]
      endPoint Solid {
        translation -6.657766697073859e-06 0.0799953 1.597536853632594e-05
        rotation -0.7901904050519178 0.4335611450206047 -0.4331556963636838 4.47991591614927
        children [
          DEF RW Shape {
            appearance FlexibleAluminiumDuct {
            }
            geometry Cylinder {
              height 0.05
              radius 0.06
            }
          }
        ]
        boundingObject USE RW
        physics Physics {
        }
      }
    }
    DEF body Pose {
      children [
        Shape {
          appearance BrushedAluminium {
          }
          geometry Box {
            size 0.1 0.1 0.1
          }
        }
      ]
    }
  ]
  name "robot2"
  boundingObject USE body
  physics Physics {
  }
  controller "llm_based"
  window "button_input"
}
