#VRML_SIM R2025a utf8

EXTERNPROTO "https://raw.githubusercontent.com/cyberbotics/webots/R2025a/projects/objects/backgrounds/protos/TexturedBackground.proto"
EXTERNPROTO "https://raw.githubusercontent.com/cyberbotics/webots/R2025a/projects/objects/backgrounds/protos/TexturedBackgroundLight.proto"
EXTERNPROTO "https://raw.githubusercontent.com/cyberbotics/webots/R2025a/projects/objects/floors/protos/RectangleArena.proto"
EXTERNPROTO "https://raw.githubusercontent.com/cyberbotics/webots/R2025a/projects/appearances/protos/BrushedAluminium.proto"
EXTERNPROTO "https://raw.githubusercontent.com/cyberbotics/webots/R2025a/projects/appearances/protos/FlexibleAluminiumDuct.proto"

WorldInfo {
}
Viewpoint {
  orientation -0.2642965978764977 -0.2287806759811614 0.9369133954899521 4.775975114141634
  position -1.0090568907514776 7.015141634110317 3.8052368556074136
}
TexturedBackground {
}
TexturedBackgroundLight {
}
RectangleArena {
  floorSize 5 5
}
DEF robot2 Robot {
  translation 0.5748845979586498 0.0005299532658304686 0.05908225988319614
  rotation 0.0026042523642812675 0.9999594163906508 0.008624583543120314 0.20291533258811273
  children [
    LED {
      translation 0 0 0.1
      children [
        Shape {
          appearance PBRAppearance {
          }
          geometry Cone {
            bottomRadius 0.05
            height 0.1
          }
        }
      ]
    }
    Gyro {
    }
    Accelerometer {
      name "gps"
    }
    DistanceSensor {
      translation 0.07 0 -5.22482e-07
      rotation 0 -1 0 -5.307179586466759e-06
      name "DS_0"
    }
    DEF LW HingeJoint {
      jointParameters HingeJointParameters {
        position 174.92629822741222
        axis 0 1 0
        anchor 0 0.1 0
      }
      device [
        RotationalMotor {
          name "MLW"
        }
      ]
      endPoint Solid {
        translation -0.00015295627825761193 -0.08000339999999945 0.0001025393688922417
        rotation -0.7902036361813368 0.43348017814900247 -0.43321259044227056 4.479843658663106
        children [
          DEF LW Shape {
            appearance FlexibleAluminiumDuct {
            }
            geometry Cylinder {
              height 0.05
              radius 0.06
            }
          }
        ]
        boundingObject USE LW
        physics Physics {
        }
        linearVelocity 0.059831288582798375 5.4386230596304025e-05 4.121038862748021e-07
        angularVelocity -0.0009072309323018436 0.9971769721406826 1.824905546089227e-07
      }
    }
    DEF RW HingeJoint {
      jointParameters HingeJointParameters {
        position 174.92629886664068
        axis 0 1 0
        anchor 0 0.1 0
      }
      device [
        RotationalMotor {
          name "MRW"
        }
      ]
      endPoint Solid {
        translation -6.6577692584453e-06 0.0799953 1.5975367468869026e-05
        rotation -0.7901903486059205 0.43356119650519787 -0.43315574780329885 4.479915846635303
        children [
          DEF RW Shape {
            appearance FlexibleAluminiumDuct {
            }
            geometry Cylinder {
              height 0.05
              radius 0.06
            }
          }
        ]
        boundingObject USE RW
        physics Physics {
        }
        linearVelocity 0.059829850738268756 5.438604711911004e-05 -1.7431632251227804e-06
        angularVelocity -0.000907052881178317 0.9971767941487472 1.4709897478747023e-06
      }
    }
    DEF body Pose {
      children [
        Shape {
          appearance BrushedAluminium {
          }
          geometry Box {
            size 0.1 0.1 0.1
          }
        }
      ]
    }
  ]
  name "robot2"
  boundingObject USE body
  physics Physics {
  }
  controller "llm_based"
  supervisor TRUE
  window "button_input"
  linearVelocity 0.05975755319128252 5.4332485552321116e-05 -6.805273778957167e-05
  angularVelocity 0.0007886106682300124 -0.00282144038736805 -0.0006875973296158117
}
