#VRML_SIM R2025a utf8

EXTERNPROTO "https://raw.githubusercontent.com/cyberbotics/webots/R2025a/projects/objects/backgrounds/protos/TexturedBackground.proto"
EXTERNPROTO "https://raw.githubusercontent.com/cyberbotics/webots/R2025a/projects/objects/backgrounds/protos/TexturedBackgroundLight.proto"
EXTERNPROTO "https://raw.githubusercontent.com/cyberbotics/webots/R2025a/projects/objects/floors/protos/RectangleArena.proto"
EXTERNPROTO "https://raw.githubusercontent.com/cyberbotics/webots/R2025a/projects/appearances/protos/BrushedAluminium.proto"
EXTERNPROTO "https://raw.githubusercontent.com/cyberbotics/webots/R2025a/projects/appearances/protos/FlexibleAluminiumDuct.proto"
EXTERNPROTO "https://raw.githubusercontent.com/cyberbotics/webots/R2025a/projects/objects/fruits/protos/Apple.proto"
EXTERNPROTO "https://raw.githubusercontent.com/cyberbotics/webots/R2025a/projects/objects/fruits/protos/Orange.proto"
EXTERNPROTO "https://raw.githubusercontent.com/cyberbotics/webots/R2025a/projects/objects/kitchen/breakfast/protos/BiscuitBox.proto"
EXTERNPROTO "https://raw.githubusercontent.com/cyberbotics/webots/R2025a/projects/objects/drinks/protos/Can.proto"
EXTERNPROTO "https://raw.githubusercontent.com/cyberbotics/webots/R2025a/projects/objects/animals/protos/Cat.proto"
EXTERNPROTO "https://raw.githubusercontent.com/cyberbotics/webots/R2025a/projects/robots/universal_robots/protos/UR10e.proto"
EXTERNPROTO "https://raw.githubusercontent.com/cyberbotics/webots/R2025a/projects/devices/robotiq/protos/Robotiq3fGripper.proto"

WorldInfo {
}
Viewpoint {
  orientation 0.07247244037563676 0.9940061788897243 0.08185023955401258 0.6741222315444958
  position -3.992102506470247 -0.6485558238328817 3.1445096817300704
}
TexturedBackground {
}
TexturedBackgroundLight {
}
RectangleArena {
  translation -0.179517 -0.12612 -8.29114e-15
  floorSize 5 5
}
DEF robot2 Robot {
  translation 0.5782289548118299 0.0015382903824786463 0.059082385897947065
  rotation 0.025699005382804535 0.9753568499821147 -0.2191314133466519 0.20797833471390795
  children [
    LED {
      translation 0 0 0.1
      children [
        Shape {
          appearance PBRAppearance {
          }
          geometry Cone {
            bottomRadius 0.05
            height 0.1
          }
        }
      ]
    }
    Gyro {
    }
    Accelerometer {
      name "gps"
    }
    DistanceSensor {
      translation 0.07 0 -5.22482e-07
      rotation 0 -1 0 -5.307179586466759e-06
      name "DS_0"
    }
    DEF LW HingeJoint {
      jointParameters HingeJointParameters {
        position 174.926308183908
        axis 0 1 0
        anchor 0 0.1 0
      }
      device [
        RotationalMotor {
          name "MLW"
        }
      ]
      endPoint Solid {
        translation -0.00015295525731723732 -0.08000339999999895 0.00010254089179569705
        rotation -0.7902071413697676 0.433476980953953 -0.43320939591757046 4.479847974590752
        children [
          DEF LW Shape {
            appearance FlexibleAluminiumDuct {
            }
            geometry Cylinder {
              height 0.05
              radius 0.06
            }
          }
        ]
        boundingObject USE LW
        physics Physics {
        }
      }
    }
    DEF RW HingeJoint {
      jointParameters HingeJointParameters {
        position 174.92629966731394
        axis 0 1 0
        anchor 0 0.1 0
      }
      device [
        RotationalMotor {
          name "MRW"
        }
      ]
      endPoint Solid {
        translation -6.65775646739359e-06 0.07999530000000002 1.5975372799561775e-05
        rotation -0.7901906304875209 0.4335609393998997 -0.43315549092261385 4.479916193776058
        children [
          DEF RW Shape {
            appearance FlexibleAluminiumDuct {
            }
            geometry Cylinder {
              height 0.05
              radius 0.06
            }
          }
        ]
        boundingObject USE RW
        physics Physics {
        }
      }
    }
    DEF body Pose {
      children [
        Shape {
          appearance BrushedAluminium {
          }
          geometry Box {
            size 0.1 0.1 0.1
          }
        }
      ]
    }
  ]
  name "robot2"
  boundingObject USE body
  physics Physics {
  }
  recognitionColors [
    0 0 0
  ]
  controller "<none>"
  window "button_input"
}
Apple {
  translation 0.08543338230550421 -1.8939183514637998 0.0497645599999917
  rotation 0.8902470772205905 0.3674813499222646 -0.2691051819633096 -2.5785819891909503
}
BiscuitBox {
  translation -0.1975387404270684 -0.3709416831353511 -0.00015696000000830004
  rotation -5.9477172972478134e-15 1.7592512640853427e-14 -1 0.0020212078647418616
}
UR10e {
  hidden translation_1 0 0 0.181
  hidden rotation_1 0 0 -1 6.933704211580152e-05
  hidden translation_2 0 0.176 0
  hidden rotation_2 0 0.9999999999999999 0 1.570694506541134
  hidden translation_3 0 -0.137 0.613
  hidden rotation_3 0 -0.9999999999999999 0 5.8129351512655076e-05
  hidden translation_4 0 0 0.571
  hidden rotation_4 0 0.9999999999999999 0 1.5707769084549654
  hidden translation_5 0 0.135 0
  hidden rotation_5 0 0 1 3.3178498674498206e-05
  hidden translation_6 0 0 0.12
  hidden rotation_6 0 1 0 6.665734289930825e-06
  hidden translation_8 -0.0455 0.0214 0.036
  hidden rotation_8 0.7068252250603847 0.7073882252405277 3.064801628222052e-06 3.141598129704522
  hidden translation_9 0.02 0 0
  hidden rotation_9 0 0 -1 2.1283115233608642e-07
  hidden translation_10 0.05 -0.028 0
  hidden rotation_10 0 0 -1 0.5200000309972507
  hidden translation_11 0.039 0 0
  hidden translation_12 -0.0455 0.0214 -0.036
  hidden rotation_12 0.7068252250603847 0.7073882252405277 3.0648016297703597e-06 3.141598129704525
  hidden translation_13 0.02 0 0
  hidden rotation_13 0 0 -1 2.086162567138673e-07
  hidden translation_14 0.05 -0.028 0
  hidden rotation_14 0 0 -1 0.5200000309972576
  hidden translation_15 0.039 0 0
  hidden translation_16 0.02 0 0
  hidden rotation_16 0 0 1 1.976862424823881e-07
  hidden translation_17 0.05 -0.028 0
  hidden rotation_17 0 0 -1 0.5199999690015773
  hidden translation_18 0.039 0 0
  translation -1.56417 0.529448 0.61
  rotation 4.66309e-07 -7.19235e-09 1 -1.5707953071795862
  controller "vlm_controller"
  selfCollision FALSE
  toolSlot [
    Robotiq3fGripper {
    }
    DistanceSensor {
      translation 0 0.1 0
      rotation 0 0 1 1.570796
    }
  ]
}
Can {
  translation -0.51504 -0.368173 0.06096265999999172
  rotation 0.0902506829703461 -0.9422223527823084 0.3226016927121704 5.221452889155254e-16
}
Cat {
  translation 0.023527 0.315267 0.01
}
Orange {
  translation -0.3712935482859985 -0.0828688109004673 0.04976455999999172
  rotation 0.940119256322704 0.3198548201027317 0.11776535122138006 1.267269156758256
}
